```js
try { 
	// ... 
} catch (err) { // <-- “error 对象”，也可以用其他参数名代替 err。 
	// {name, message, stack} = err; 
	// 错误名称，错误信息，错误栈
	// ... 
} finally { 
	//... 总是会执行的代码 ... 
}
```
# 执行步骤
1.  首先，执行 `try {...}` 中的代码。
2.  如果这里没有错误，则忽略 `catch (err)`：执行到 `try` 的末尾并跳过 `catch` 继续执行`finally`。
	1.  如果这里出现错误，则 `try` 执行停止，控制流转向 `catch (err)` 的开头。变量 `err`（我们可以使用任何名称）将包含一个 error 对象，该对象包含了所发生事件的详细信息。`catch` 之后，有没有`error`，都会执行`finally`。如果`catch`内也抛出错误，那也是`finally`执行后再抛。

# 要使得 `try...catch` 能工作
1. 代码必须是可执行的。
	换句话说，它必须是有效的 JavaScript 代码。如果代码包含语法错误，那么 `try..catch` 将无法正常工作。JavaScript 引擎首先会读取代码，然后运行它。在读取阶段发生的错误被称为“解析时间（parse-time）”错误，并且无法恢复（从该代码内部）。这是因为引擎无法理解该代码。所以，`try...catch` 只能处理有效代码中出现的错误。这类错误被称为“运行时的错误（runtime errors）”，有时被称为“异常（exceptions）”。
2. 必须要是"同步"的
	例如在 `setTimeout` 中，则 `try...catch` 不会捕获到异常。因为 `try...catch` 包裹了计划要执行的函数，该函数本身要稍后才执行，这时引擎已经离开了 `try...catch` 结构。为了捕获到计划的（scheduled）函数中的异常，那么 `try...catch` 必须在这个函数内。

# [Throw” 操作符](https://zh.javascript.info/try-catch#throw-cao-zuo-fu)
```js
//这个例子中的 `readData` 只知道如何处理 `SyntaxError`，而外部的 `try...catch` 知道如何处理任意的 error。

function readData() {
	let json = `{"age": 30}`;
	try {
		blabla(); //error!
	}catch(err){
		//...
		if(!(err instanceof SyntaxError)) {
			throw err; //再次抛出（不知道如何处理它）
		}
	}
}

try {
	readData();
}catch(err){
	alert("External catch got: " + err); //捕获了上面的错误。
}

```

# 全局错误处理程序 `window.onerror` 
通常不是恢复脚本的执行 — 如果发生编程错误，那这几乎是不可能的，它的作用是将错误信息发送给开发者。

# 自定义错误
```js
class FormatError extends SyntaxError {
	constructor(message){
		super(message)
		this.name = this.constructor.name;
	}
} 

let err = new FormatError('formatting error');
const {name, message, stack} = err;
```